Workbook

Sheet Sales Data
A1: Date | B1: Month | C1: Region | D1: Sales Rep | E1: Product | F1: Category | G1: Units Sold | H1: Unit Price | I1: Revenue | J1: COGS | K1: Gross Profit | L1: Margin %
A2: 45619 | B2: Nov | C2: South | D2: Bob Ochieng | E2: Wireless Mouse | F2: Peripherals | G2: 2 | H2: 31.1 | I2: =G2*H2 -> 62.2 | J2: =I2*0.499 -> 31.0378 | K2: =I2-J2 -> 31.1622 | L2: =IF(I2=0,0,K2/I2) -> 0.501
A3: 45638 | B3: Dec | C3: South | D3: David Kamau | E3: Wireless Mouse | F3: Peripherals | G3: 38 | H3: 28.32 | I3: =G3*H3 -> 1076.16 | J3: =I3*0.456 -> 490.72896 | K3: =I3-J3 -> 585.43104 | L3: =IF(I3=0,0,K3/I3) -> 0.544
A4: 45550 | B4: Sep | C4: Central | D4: Grace Akinyi | E4: Laptop Pro | F4: Computers | G4: 36 | H4: 1181.64 | I4: =G4*H4 -> 42539.04 | J4: =I4*0.58 -> 24672.643 | K4: =I4-J4 -> 17866.397 | L4: =IF(I4=0,0,K4/I4) -> 0.42
A5: 45404 | B5: Apr | C5: South | D5: Grace Akinyi | E5: Ergonomic Chair | F5: Furniture | G5: 38 | H5: 419.12 | I5: =G5*H5 -> 15926.56 | J5: =I5*0.624 -> 9938.1734 | K5: =I5-J5 -> 5988.3866 | L5: =IF(I5=0,0,K5/I5) -> 0.376
A6: 45466 | B6: Jun | C6: North | D6: Bob Ochieng | E6: USB-C Hub | F6: Accessories | G6: 10 | H6: 41.16 | I6: =G6*H6 -> 411.6 | J6: =I6*0.603 -> 248.1948 | K6: =I6-J6 -> 163.4052 | L6: =IF(I6=0,0,K6/I6) -> 0.397
A7: 45486 | B7: Jul | C7: North | D7: Henry Mwenda | E7: Wireless Mouse | F7: Peripherals | G7: 23 | H7: 32.02 | I7: =G7*H7 -> 736.46 | J7: =I7*0.571 -> 420.51866 | K7: =I7-J7 -> 315.94134 | L7: =IF(I7=0,0,K7/I7) -> 0.429
A8: 45566 | B8: Oct | C8: Central | D8: Frank Otieno | E8: Wireless Mouse | F8: Peripherals | G8: 25 | H8: 25.34 | I8: =G8*H8 -> 633.5 | J8: =I8*0.509 -> 322.4515 | K8: =I8-J8 -> 311.0485 | L8: =IF(I8=0,0,K8/I8) -> 0.491
A9: 45587 | B9: Oct | C9: East | D9: Bob Ochieng | E9: Mechanical Keyboard | F9: Peripherals | G9: 46 | H9: 77.51 | I9: =G9*H9 -> 3565.46 | J9: =I9*0.582 -> 2075.0977 | K9: =I9-J9 -> 1490.3623 | L9: =IF(I9=0,0,K9/I9) -> 0.418
A10: 45411 | B10: Apr | C10: East | D10: Carol Njeri | E10: Wireless Mouse | F10: Peripherals | G10: 25 | H10: 27.07 | I10: =G10*H10 -> 676.75 | J10: =I10*0.577 -> 390.48475 | K10: =I10-J10 -> 286.26525 | L10: =IF(I10=0,0,K10/I10) -> 0.423
A11: 45481 | B11: Jul | C11: North | D11: Carol Njeri | E11: Webcam HD | F11: Accessories | G11: 14 | H11: 135.59 | I11: =G11*H11 -> 1898.26 | J11: =I11*0.59 -> 1119.9734 | K11: =I11-J11 -> 778.2866 | L11: =IF(I11=0,0,K11/I11) -> 0.41
A12: 45565 | B12: Sep | C12: Central | D12: David Kamau | E12: Mechanical Keyboard | F12: Peripherals | G12: 11 | H12: 87.99 | I12: =G12*H12 -> 967.89 | J12: =I12*0.504 -> 487.81656 | K12: =I12-J12 -> 480.07344 | L12: =IF(I12=0,0,K12/I12) -> 0.496
A13: 45642 | B13: Dec | C13: North | D13: Frank Otieno | E13: Webcam HD | F13: Accessories | G13: 50 | H13: 139.68 | I13: =G13*H13 -> 6984 | J13: =I13*0.496 -> 3464.064 | K13: =I13-J13 -> 3519.936 | L13: =IF(I13=0,0,K13/I13) -> 0.504
A14: 45497 | B14: Jul | C14: East | D14: David Kamau | E14: USB-C Hub | F14: Accessories | G14: 5 | H14: 41.1 | I14: =G14*H14 -> 205.5 | J14: =I14*0.639 -> 131.3145 | K14: =I14-J14 -> 74.1855 | L14: =IF(I14=0,0,K14/I14) -> 0.361
A15: 45627 | B15: Dec | C15: South | D15: Eve Wanjiku | E15: Ergonomic Chair | F15: Furniture | G15: 26 | H15: 500.82 | I15: =G15*H15 -> 13021.32 | J15: =I15*0.579 -> 7539.3443 | K15: =I15-J15 -> 5481.9757 | L15: =IF(I15=0,0,K15/I15) -> 0.421
A16: 45363 | B16: Mar | C16: Central | D16: Grace Akinyi | E16: Mechanical Keyboard | F16: Peripherals | G16: 48 | H16: 90.64 | I16: =G16*H16 -> 4350.72 | J16: =I16*0.503 -> 2188.4122 | K16: =I16-J16 -> 2162.3078 | L16: =IF(I16=0,0,K16/I16) -> 0.497
A17: 45590 | B17: Oct | C17: Central | D17: Henry Mwenda | E17: Standing Desk | F17: Furniture | G17: 24 | H17: 365.4 | I17: =G17*H17 -> 8769.6 | J17: =I17*0.65 -> 5700.24 | K17: =I17-J17 -> 3069.36 | L17: =IF(I17=0,0,K17/I17) -> 0.35
A18: 45338 | B18: Feb | C18: West | D18: Bob Ochieng | E18: Laptop Pro | F18: Computers | G18: 8 | H18: 1163.71 | I18: =G18*H18 -> 9309.68 | J18: =I18*0.482 -> 4487.2658 | K18: =I18-J18 -> 4822.4142 | L18: =IF(I18=0,0,K18/I18) -> 0.518
A19: 45489 | B19: Jul | C19: Central | D19: Alice Mwangi | E19: Standing Desk | F19: Furniture | G19: 39 | H19: 458.39 | I19: =G19*H19 -> 17877.21 | J19: =I19*0.556 -> 9939.7288 | K19: =I19-J19 -> 7937.4812 | L19: =IF(I19=0,0,K19/I19) -> 0.444
A20: 45640 | B20: Dec | C20: East | D20: Bob Ochieng | E20: Wireless Mouse | F20: Peripherals | G20: 44 | H20: 32.35 | I20: =G20*H20 -> 1423.4 | J20: =I20*0.6 -> 854.04 | K20: =I20-J20 -> 569.36 | L20: =IF(I20=0,0,K20/I20) -> 0.4
A21: 45442 | B21: May | C21: East | D21: Carol Njeri | E21: Standing Desk | F21: Furniture | G21: 11 | H21: 393.46 | I21: =G21*H21 -> 4328.06 | J21: =I21*0.641 -> 2774.2865 | K21: =I21-J21 -> 1553.7735 | L21: =IF(I21=0,0,K21/I21) -> 0.359
A22: 45551 | B22: Sep | C22: Central | D22: David Kamau | E22: Wireless Mouse | F22: Peripherals | G22: 41 | H22: 27.25 | I22: =G22*H22 -> 1117.25 | J22: =I22*0.578 -> 645.7705 | K22: =I22-J22 -> 471.4795 | L22: =IF(I22=0,0,K22/I22) -> 0.422
A23: 45370 | B23: Mar | C23: Central | D23: Alice Mwangi | E23: Webcam HD | F23: Accessories | G23: 49 | H23: 115.9 | I23: =G23*H23 -> 5679.1 | J23: =I23*0.641 -> 3640.3031 | K23: =I23-J23 -> 2038.7969 | L23: =IF(I23=0,0,K23/I23) -> 0.359
A24: 45598 | B24: Nov | C24: East | D24: David Kamau | E24: Webcam HD | F24: Accessories | G24: 32 | H24: 110.4 | I24: =G24*H24 -> 3532.8 | J24: =I24*0.636 -> 2246.8608 | K24: =I24-J24 -> 1285.9392 | L24: =IF(I24=0,0,K24/I24) -> 0.364
A25: 45321 | B25: Jan | C25: West | D25: Bob Ochieng | E25: Mechanical Keyboard | F25: Peripherals | G25: 37 | H25: 100.93 | I25: =G25*H25 -> 3734.41 | J25: =I25*0.467 -> 1743.9695 | K25: =I25-J25 -> 1990.4405 | L25: =IF(I25=0,0,K25/I25) -> 0.533
A26: 45564 | B26: Sep | C26: South | D26: Eve Wanjiku | E26: 4K Monitor | F26: Displays | G26: 9 | H26: 627.71 | I26: =G26*H26 -> 5649.39 | J26: =I26*0.639 -> 3609.9602 | K26: =I26-J26 -> 2039.4298 | L26: =IF(I26=0,0,K26/I26) -> 0.361
A27: 45562 | B27: Sep | C27: South | D27: Eve Wanjiku | E27: Standing Desk | F27: Furniture | G27: 14 | H27: 450.34 | I27: =G27*H27 -> 6304.76 | J27: =I27*0.601 -> 3789.1608 | K27: =I27-J27 -> 2515.5992 | L27: =IF(I27=0,0,K27/I27) -> 0.399
A28: 45496 | B28: Jul | C28: South | D28: David Kamau | E28: Webcam HD | F28: Accessories | G28: 29 | H28: 144.47 | I28: =G28*H28 -> 4189.63 | J28: =I28*0.54 -> 2262.4002 | K28: =I28-J28 -> 1927.2298 | L28: =IF(I28=0,0,K28/I28) -> 0.46
A29: 45324 | B29: Feb | C29: South | D29: Alice Mwangi | E29: Webcam HD | F29: Accessories | G29: 2 | H29: 132.42 | I29: =G29*H29 -> 264.84 | J29: =I29*0.496 -> 131.36064 | K29: =I29-J29 -> 133.47936 | L29: =IF(I29=0,0,K29/I29) -> 0.504
A30: 45328 | B30: Feb | C30: East | D30: Bob Ochieng | E30: Laptop Pro | F30: Computers | G30: 15 | H30: 1130.42 | I30: =G30*H30 -> 16956.3 | J30: =I30*0.456 -> 7732.0728 | K30: =I30-J30 -> 9224.2272 | L30: =IF(I30=0,0,K30/I30) -> 0.544
A31: 45555 | B31: Sep | C31: South | D31: Henry Mwenda | E31: Mechanical Keyboard | F31: Peripherals | G31: 18 | H31: 93.51 | I31: =G31*H31 -> 1683.18 | J31: =I31*0.493 -> 829.80774 | K31: =I31-J31 -> 853.37226 | L31: =IF(I31=0,0,K31/I31) -> 0.507
A32: 45416 | B32: May | C32: West | D32: Frank Otieno | E32: Ergonomic Chair | F32: Furniture | G32: 27 | H32: 407.3 | I32: =G32*H32 -> 10997.1 | J32: =I32*0.469 -> 5157.6399 | K32: =I32-J32 -> 5839.4601 | L32: =IF(I32=0,0,K32/I32) -> 0.531
A33: 45508 | B33: Aug | C33: North | D33: Alice Mwangi | E33: Standing Desk | F33: Furniture | G33: 30 | H33: 442.55 | I33: =G33*H33 -> 13276.5 | J33: =I33*0.461 -> 6120.4665 | K33: =I33-J33 -> 7156.0335 | L33: =IF(I33=0,0,K33/I33) -> 0.539
A34: 45498 | B34: Jul | C34: West | D34: Carol Njeri | E34: Webcam HD | F34: Accessories | G34: 7 | H34: 119.27 | I34: =G34*H34 -> 834.89 | J34: =I34*0.488 -> 407.42632 | K34: =I34-J34 -> 427.46368 | L34: =IF(I34=0,0,K34/I34) -> 0.512
A35: 45508 | B35: Aug | C35: North | D35: Henry Mwenda | E35: 4K Monitor | F35: Displays | G35: 18 | H35: 592.28 | I35: =G35*H35 -> 10661.04 | J35: =I35*0.625 -> 6663.15 | K35: =I35-J35 -> 3997.89 | L35: =IF(I35=0,0,K35/I35) -> 0.375
A36: 45573 | B36: Oct | C36: North | D36: Bob Ochieng | E36: Wireless Mouse | F36: Peripherals | G36: 4 | H36: 30.32 | I36: =G36*H36 -> 121.28 | J36: =I36*0.558 -> 67.67424 | K36: =I36-J36 -> 53.60576 | L36: =IF(I36=0,0,K36/I36) -> 0.442
A37: 45413 | B37: May | C37: West | D37: Alice Mwangi | E37: 4K Monitor | F37: Displays | G37: 27 | H37: 596.42 | I37: =G37*H37 -> 16103.34 | J37: =I37*0.493 -> 7938.9466 | K37: =I37-J37 -> 8164.3934 | L37: =IF(I37=0,0,K37/I37) -> 0.507
A38: 45376 | B38: Mar | C38: West | D38: Eve Wanjiku | E38: Standing Desk | F38: Furniture | G38: 1 | H38: 457.09 | I38: =G38*H38 -> 457.09 | J38: =I38*0.503 -> 229.91627 | K38: =I38-J38 -> 227.17373 | L38: =IF(I38=0,0,K38/I38) -> 0.497
A39: 45508 | B39: Aug | C39: North | D39: Alice Mwangi | E39: Ergonomic Chair | F39: Furniture | G39: 10 | H39: 407.23 | I39: =G39*H39 -> 4072.3 | J39: =I39*0.494 -> 2011.7162 | K39: =I39-J39 -> 2060.5838 | L39: =IF(I39=0,0,K39/I39) -> 0.506
A40: 45452 | B40: Jun | C40: Central | D40: Carol Njeri | E40: Laptop Pro | F40: Computers | G40: 4 | H40: 1331.8 | I40: =G40*H40 -> 5327.2 | J40: =I40*0.551 -> 2935.2872 | K40: =I40-J40 -> 2391.9128 | L40: =IF(I40=0,0,K40/I40) -> 0.449
...

Sheet Employee Data
A1: Employee ID | B1: Name | C1: Department | D1: Role | E1: Hire Date | F1: Salary (KES) | G1: Years Exp | H1: Performance | I1: Satisfaction | J1: Remote %
A2: EMP1000 | B2: Amara Osei | C2: HR | D2: Coordinator | E2: 42903 | F2: 1425396 | G2: 2 | H2: 5 | I2: 4.6 | J2: 20
A3: EMP1001 | B3: Brice Mutua | C3: Design | D3: Designer | E3: 44093 | F3: 1880484 | G3: 8 | H3: 4.5 | I3: 4.1 | J3: 80
A4: EMP1002 | B4: Cleo Nzioka | C4: Marketing | D4: Analyst | E4: 43669 | F4: 2981364 | G4: 8 | H4: 3.8 | I4: 4.5 | J4: 80
A5: EMP1003 | B5: Diana Weru | C5: Marketing | D5: Analyst | E5: 44138 | F5: 2135496 | G5: 8 | H5: 4.2 | I5: 3.7 | J5: 80
A6: EMP1004 | B6: Elias Korir | C6: Sales | D6: Rep | E6: 44467 | F6: 894312 | G6: 14 | H6: 2.8 | I6: 3.3 | J6: 20
A7: EMP1005 | B7: Fatuma Hassan | C7: Sales | D7: Senior Rep | E7: 43268 | F7: 1613532 | G7: 14 | H7: 2.7 | I7: 3.4 | J7: 80
A8: EMP1006 | B8: George Maina | C8: HR | D8: Coordinator | E8: 43756 | F8: 1013892 | G8: 9 | H8: 4.1 | I8: 4.2 | J8: 80
A9: EMP1007 | B9: Hilda Chebet | C9: Sales | D9: Rep | E9: 44106 | F9: 809244 | G9: 2 | H9: 2.6 | I9: 4.3 | J9: 80
A10: EMP1008 | B10: Ivan Omondi | C10: HR | D10: Director | E10: 43387 | F10: 2664396 | G10: 11 | H10: 2.6 | I10: 4.8 | J10: 80
A11: EMP1009 | B11: Jane Gitonga | C11: HR | D11: Director | E11: 43685 | F11: 2874792 | G11: 7 | H11: 3.2 | I11: 3.1 | J11: 0
A12: EMP1010 | B12: Kevin Njoroge | C12: Sales | D12: Senior Rep | E12: 44423 | F12: 1361796 | G12: 6 | H12: 4 | I12: 3.6 | J12: 100
A13: EMP1011 | B13: Lydia Waweru | C13: Operations | D13: Director | E13: 44017 | F13: 1885608 | G13: 9 | H13: 3.9 | I13: 3.6 | J13: 50
... A31: EMP1029 | B31: Dora Musyoka | C31: HR | D31: Director | E31: 43457 | F31: 2258268 | G31: 6 | H31: 3.7 | I31: 4.1 | J31: 100

Sheet Summary Dashboard
A1: 📊 DATAFORGE SAMPLE DATASET
A2: Auto-generated sample dataset for testing the DataForge AI Analysis Platform
A4: SALES SUMMARY
A5: Total Transactions | B5: ='Sales Data'!G252 -> 6387 | C5: Total Units Sold | D5: ='Sales Data'!G252 -> 6387
A6: Total Revenue (KES) | B6: =ROUND('Sales Data'!I252,2) -> 2265793.4 | C6: Total COGS (KES) | D6: =ROUND('Sales Data'!J252,2) -> 1219175.9
A7: Total Gross Profit | B7: =ROUND('Sales Data'!K252,2) -> 1046617.5 | C7: Overall Margin | D7: ='Sales Data'!L252 -> 0.46192096
A9: EMPLOYEE SUMMARY
A10: Total Employees | B10: =COUNTA('Employee Data'!A2:A31) -> 30 | C10: Avg Salary (KES) | D10: =AVERAGE('Employee Data'!F2:F31) -> 1916802
A11: Avg Performance | B11: =AVERAGE('Employee Data'!H2:H31) -> 3.5733333 | C11: Avg Satisfaction | D11: =AVERAGE('Employee Data'!I2:I31) -> 4.11
A12: Avg Years Exp | B12: =AVERAGE('Employee Data'!G2:G31) -> 8.1333333 | C12: Avg Remote % | D12: =AVERAGE('Employee Data'!J2:J31) -> 59.666667
A14: 📌 Suggested Analyses
A15: → Show monthly revenue trend and identify best performing month
A16: → Compare gross margin % across product categories
A17: → Analyze salary distribution by department
A18: → Find correlation between experience and performance rating
A19: → Identify top 5 sales reps by total revenue
A20: → Show regional sales breakdown with a pie chart
